<?xml version="1.0" ?>
<!-- =================================================================================== -->
<!-- |    This document was autogenerated by xacro from main.xacro                     | -->
<!-- |    EDITING THIS FILE BY HAND IS NOT RECOMMENDED                                 | -->
<!-- =================================================================================== -->
<robot name="RX20_16">
  <!--fake 0.02 real 0.139-->
  <gazebo>
    <!-- Load ros_control plugin using the steer_bot_hardware_gazebo
    implementation of the hardware_interface::RobotHW -->
    <plugin filename="libgazebo_ros_control.so" name="gazebo_ros_control">
      <robotNamespace>/RX20_16</robotNamespace>
      <robotSimType>gazebo_ros_control/DefaultRobotHWSim</robotSimType>
      <legacyModeNS>false</legacyModeNS>
    </plugin>
  </gazebo>
  <link name="base_footprint"/>
  <link name="base_scan"/>
  <link name="base_link">
    <inertial>
      <origin rpy="0 0 0" xyz="-0.8 0 0.417"/>
      <inertia ixx="1.5893541666666666" ixy="0" ixz="0" iyy="3.411561666666666" iyz="0" izz="3.838874166666667"/>
      <mass value="10"/>
    </inertial>
    <collision>
      <origin rpy="0 0 0" xyz="0 0 0"/>
      <geometry>
        <mesh filename="/home/hnk/auto_forklift_pallet_detection/src/forklift_simulator/urdf/RX20_16/meshes/body.dae"/>
      </geometry>
    </collision>
    <visual>
      <origin rpy="0 0 0" xyz="0 0 0"/>
      <geometry>
        <mesh filename="/home/hnk/auto_forklift_pallet_detection/src/forklift_simulator/urdf/RX20_16/meshes/body.dae"/>
      </geometry>
    </visual>
  </link>
  <link name="imu_link"/>
  <joint name="imu_joint" type="fixed">
    <parent link="base_link"/>
    <child link="imu_link"/>
    <origin rpy="0 0 0" xyz="0.0 0 0.068"/>
  </joint>
  <joint name="base_joint" type="fixed">
    <parent link="base_footprint"/>
    <child link="base_link"/>
    <origin rpy="0 0 0" xyz="0.0 0 0.0"/>
    <axis xyz="0 0 1"/>
  </joint>
  <joint name="scan" type="fixed">
    <parent link="base_footprint"/>
    <child link="base_scan"/>
    <origin rpy="0 0 0" xyz="0.0 0 0.0"/>
    <axis xyz="0 0 1"/>
  </joint>
  <!--
  <rosparam command="load" file="$(forklift_simulator)/config/joint_state_trajectory.yaml" />
  <plugin name="joint_state_trajectory_publisher" filename="libjoint_state_trajectory_publisher.so">
    <ros2_namespace>/RX20_16</ros2_namespace>
    <publisher_topic>joint_states</publisher_topic>
  </plugin>
  <plugin name="joint_state_trajectory_subscriber" filename="libjoint_state_trajectory_subscriber.so">
    <ros2_namespace>/RX20_16</ros2_namespace>
    <subscriber_topic>joint_trajectory</subscriber_topic>
  </plugin> -->
  <link name="tilt_link">
    <inertial>
      <origin rpy="0 0 0" xyz="0 0 0"/>
      <inertia ixx="0.00010416666666666669" ixy="0" ixz="0" iyy="0.00035416666666666675" iyz="0" izz="0.00041666666666666675"/>
      <mass value="0.1"/>
    </inertial>
    <collision>
      <origin rpy="0 0 0" xyz="0 0 0"/>
      <geometry>
        <mesh filename="/home/hnk/auto_forklift_pallet_detection/src/forklift_simulator/urdf/RX20_16/meshes/tilt_link.dae"/>
      </geometry>
    </collision>
    <visual>
      <origin rpy="0 0 0" xyz="0 0 0"/>
      <geometry>
        <mesh filename="/home/hnk/auto_forklift_pallet_detection/src/forklift_simulator/urdf/RX20_16/meshes/tilt_link.dae"/>
      </geometry>
    </visual>
  </link>
  <joint name="tilt_joint" type="revolute">
    <parent link="base_link"/>
    <child link="tilt_link"/>
    <origin rpy="0 0 0" xyz="0.18 0 0.0"/>
    <axis xyz="0 1 0"/>
    <limit effort="50" lower="-0.087" upper="0.105" velocity="0.3"/>
    <dynamics damping="10" friction="1"/>
  </joint>
  <link name="lift_link">
    <inertial>
      <origin rpy="0 0 0" xyz="0 0 0"/>
      <inertia ixx="0.00010416666666666669" ixy="0" ixz="0" iyy="0.00035416666666666675" iyz="0" izz="0.00041666666666666675"/>
      <mass value="0.1"/>
    </inertial>
    <collision>
      <origin rpy="0 0 0" xyz="0 0 0"/>
      <geometry>
        <mesh filename="/home/hnk/auto_forklift_pallet_detection/src/forklift_simulator/urdf/RX20_16/meshes/lift_link.dae"/>
      </geometry>
    </collision>
    <visual>
      <origin rpy="0 0 0" xyz="0 0 0"/>
      <geometry>
        <mesh filename="/home/hnk/auto_forklift_pallet_detection/src/forklift_simulator/urdf/RX20_16/meshes/lift_link.dae"/>
      </geometry>
    </visual>
  </link>
  <joint name="lift_joint" type="prismatic">
    <parent link="tilt_link"/>
    <child link="lift_link"/>
    <origin rpy="0 0 0" xyz="0.134 0 0.22"/>
    <axis xyz="0 0 1"/>
    <limit effort="100" lower="-0.2" upper="2" velocity="0.3"/>
    <dynamics damping="100.0" friction="1"/>
  </joint>
  <link name="sideshift_link">
    <inertial>
      <origin rpy="0 0 0" xyz="0 0 0"/>
      <inertia ixx="0.00010416666666666669" ixy="0" ixz="0" iyy="0.00035416666666666675" iyz="0" izz="0.00041666666666666675"/>
      <mass value="0.1"/>
    </inertial>
    <collision>
      <origin rpy="0 0 0" xyz="0 0 0"/>
      <geometry>
        <mesh filename="/home/hnk/auto_forklift_pallet_detection/src/forklift_simulator/urdf/RX20_16/meshes/sideshift_link.dae"/>
      </geometry>
    </collision>
    <visual>
      <origin rpy="0 0 0" xyz="0 0 0"/>
      <geometry>
        <mesh filename="/home/hnk/auto_forklift_pallet_detection/src/forklift_simulator/urdf/RX20_16/meshes/sideshift_link.dae"/>
      </geometry>
    </visual>
  </link>
  <joint name="sideshift_joint" type="prismatic">
    <parent link="lift_link"/>
    <child link="sideshift_link"/>
    <origin rpy="0 0 0" xyz="0.06 0 -0.25"/>
    <axis xyz="0 1 0"/>
    <limit effort="100" lower="-0.2" upper="0.2" velocity="0.3"/>
    <dynamics damping="10" friction="1"/>
  </joint>
  <transmission name="tran1">
    <type>transmission_interface/SimpleTransmission</type>
    <joint name="tilt_joint">
      <hardwareInterface>hardware_interface/EffortJointInterface</hardwareInterface>
    </joint>
    <actuator name="motor1">
      <hardwareInterface>hardware_interface/EffortJointInterface</hardwareInterface>
      <mechanicalReduction>1</mechanicalReduction>
    </actuator>
  </transmission>
  <transmission name="tran2">
    <type>transmission_interface/SimpleTransmission</type>
    <joint name="lift_joint">
      <hardwareInterface>hardware_interface/EffortJointInterface</hardwareInterface>
    </joint>
    <actuator name="motor2">
      <hardwareInterface>hardware_interface/EffortJointInterface</hardwareInterface>
      <mechanicalReduction>1</mechanicalReduction>
    </actuator>
  </transmission>
  <transmission name="tran3">
    <type>transmission_interface/SimpleTransmission</type>
    <joint name="sideshift_joint">
      <hardwareInterface>hardware_interface/EffortJointInterface</hardwareInterface>
    </joint>
    <actuator name="motor3">
      <hardwareInterface>hardware_interface/EffortJointInterface</hardwareInterface>
      <mechanicalReduction>1</mechanicalReduction>
    </actuator>
  </transmission>
  <gazebo>
    <plugin filename="libgazebo_ros_control.so" name="gazebo_ros_control">
      <robotNamespace>/RX20_16</robotNamespace>
      <robotSimType>gazebo_ros_control/DefaultRobotHWSim</robotSimType>
    </plugin>
  </gazebo>
  <link name="box1">
    <collision>
      <geometry>
        <box size="0.8 0.08 0.042"/>
      </geometry>
    </collision>
    <!-- <visual>
      <geometry>
        <box size="0.8 0.08 0.04"/>
      </geometry>
    </visual> -->
  </link>
  <joint name="pad_joint1" type="fixed">
    <parent link="sideshift_link"/>
    <child link="box1"/>
    <origin rpy="0 0 0" xyz="0.4 0.189 0.02"/>
    <axis xyz="0 0 1"/>
  </joint>
  <link name="box2">
    <collision>
      <geometry>
        <box size="0.8 0.08 0.042"/>
      </geometry>
    </collision>
    <!-- <visual>
      <geometry>
        <box size="0.8 0.08 0.04"/>
      </geometry>
    </visual> -->
  </link>
  <joint name="pad_joint2" type="fixed">
    <parent link="sideshift_link"/>
    <child link="box2"/>
    <origin rpy="0 0 0" xyz="0.4 -0.189 0.02"/>
    <axis xyz="0 0 1"/>
  </joint>
  <link name="box">
    <collision>
      <geometry>
        <box size="0.02 0.2 0.1"/>
      </geometry>
    </collision>
    <!-- <visual>
      <geometry>
        <box size="0.02 0.2 0.1"/>
      </geometry>
    </visual> -->
  </link>
  <joint name="pad_joint" type="fixed">
    <parent link="sideshift_link"/>
    <child link="box"/>
    <origin rpy="0 0 0" xyz="0.0 0.0 0.05"/>
    <axis xyz="0 0 1"/>
  </joint>
  <material name="red">
    <color rgba="0.8 0 0 1"/>
  </material>
  <material name="green">
    <color rgba="0 0.8 0 1"/>
  </material>
  <material name="blue">
    <color rgba="0 0 0.8 1"/>
  </material>
  <material name="yellow">
    <color rgba="0.8 0.8 0 1"/>
  </material>
  <material name="orange">
    <color rgba="0.8 0.25 0 1"/>
  </material>
  <material name="black">
    <color rgba="0 0 0 1"/>
  </material>
  <material name="dark_gray">
    <color rgba="0.5 0.5 0.5 1"/>
  </material>
  <material name="gray">
    <color rgba="0.753 0.753 0.753 1"/>
  </material>
  <material name="silver">
    <color rgba="0.88 0.88 0.88 1"/>
  </material>
  <material name="white">
    <color rgba="1 1 1 1"/>
  </material>
  <material name="camera_aluminum">
    <color rgba="0.5 0.5 0.5 1"/>
  </material>
  <!-- camera body, with origin at bottom screw mount -->
  <joint name="camera_joint" type="fixed">
    <origin rpy="0 0 0" xyz="0.02 0 0.1"/>
    <parent link="lift_link"/>
    <child link="camera_bottom_screw_frame"/>
  </joint>
  <link name="camera_bottom_screw_frame"/>
  <joint name="camera_link_joint" type="fixed">
    <origin rpy="0 0 0" xyz="0 0.0175 0.0125"/>
    <parent link="camera_bottom_screw_frame"/>
    <child link="camera_link"/>
  </joint>
  <link name="camera_link">
    <visual>
      <origin rpy="1.5707963267948966 0 1.5707963267948966" xyz="0.0149 -0.0175 0"/>
      <geometry>
        <!-- <box size="${d435_cam_width} ${d435_cam_height} ${d435_cam_depth}"/> -->
        <mesh filename="package://forklift_simulator/urdf/RX20_16/meshes/d435.dae"/>
        <!--<mesh filename="package://forklift_simulator/urdf/RX20_16/meshes/d435/d435.dae" />-->
      </geometry>
      <material name="camera_aluminum"/>
    </visual>
    <collision>
      <origin rpy="0 0 0" xyz="0 -0.0175 0"/>
      <geometry>
        <box size="0.02505 0.09 0.025"/>
      </geometry>
    </collision>
    <inertial>
      <!-- The following are not reliable values, and should not be used for modeling -->
      <mass value="0.564"/>
      <origin xyz="0 0 0"/>
      <inertia ixx="0.003881243" ixy="0.0" ixz="0.0" iyy="0.000498940" iyz="0.0" izz="0.003879257"/>
    </inertial>
  </link>
  <!-- camera depth joints and links -->
  <joint name="camera_depth_joint" type="fixed">
    <origin rpy="0 0 0" xyz="0 0 0"/>
    <parent link="camera_link"/>
    <child link="camera_depth_frame"/>
  </joint>
  <link name="camera_depth_frame"/>
  <joint name="camera_depth_optical_joint" type="fixed">
    <origin rpy="-1.5707963267948966 0 -1.5707963267948966" xyz="0 0 0"/>
    <parent link="camera_depth_frame"/>
    <child link="camera_depth_optical_frame"/>
  </joint>
  <link name="camera_depth_optical_frame"/>
  <!-- camera left IR joints and links -->
  <joint name="camera_left_ir_joint" type="fixed">
    <origin rpy="0 0 0" xyz="0 0.0 0"/>
    <parent link="camera_depth_frame"/>
    <child link="camera_left_ir_frame"/>
  </joint>
  <link name="camera_left_ir_frame"/>
  <joint name="camera_left_ir_optical_joint" type="fixed">
    <origin rpy="-1.5707963267948966 0 -1.5707963267948966" xyz="0 0 0"/>
    <parent link="camera_left_ir_frame"/>
    <child link="camera_left_ir_optical_frame"/>
  </joint>
  <link name="camera_left_ir_optical_frame"/>
  <!-- camera right IR joints and links -->
  <joint name="camera_right_ir_joint" type="fixed">
    <origin rpy="0 0 0" xyz="0 -0.05 0"/>
    <parent link="camera_depth_frame"/>
    <child link="camera_right_ir_frame"/>
  </joint>
  <link name="camera_right_ir_frame"/>
  <joint name="camera_right_ir_optical_joint" type="fixed">
    <origin rpy="-1.5707963267948966 0 -1.5707963267948966" xyz="0 0 0"/>
    <parent link="camera_right_ir_frame"/>
    <child link="camera_right_ir_optical_frame"/>
  </joint>
  <link name="camera_right_ir_optical_frame"/>
  <!-- camera color joints and links -->
  <joint name="camera_color_joint" type="fixed">
    <origin rpy="0 0 0" xyz="0 0.015 0"/>
    <parent link="camera_depth_frame"/>
    <child link="camera_color_frame"/>
  </joint>
  <link name="camera_color_frame"/>
  <joint name="camera_color_optical_joint" type="fixed">
    <origin rpy="-1.5707963267948966 0 -1.5707963267948966" xyz="0 0 0"/>
    <parent link="camera_color_frame"/>
    <child link="camera_color_optical_frame"/>
  </joint>
  <link name="camera_color_optical_frame"/>
  <gazebo reference="camera_link">
    <self_collide>0</self_collide>
    <enable_wind>0</enable_wind>
    <kinematic>0</kinematic>
    <gravity>1</gravity>
    <!--<mu>1</mu>-->
    <mu2>1</mu2>
    <fdir1>0 0 0</fdir1>
    <!--<slip1>0</slip1>
      <slip2>0</slip2>-->
    <kp>1e+13</kp>
    <kd>1</kd>
    <!--<max_vel>0.01</max_vel>
      <min_depth>0</min_depth>-->
    <sensor name="cameracolor" type="camera">
      <camera name="camera">
        <horizontal_fov>1.2112585008840648</horizontal_fov>
        <image>
          <width>848</width>
          <height>480</height>
          <format>RGB_INT8</format>
        </image>
        <clip>
          <near>0.1</near>
          <far>100</far>
        </clip>
        <noise>
          <type>gaussian</type>
          <mean>0.0</mean>
          <stddev>0.007</stddev>
          <type>gaussian</type>
          <mean>0.0</mean>
          <stddev>0.007</stddev>
        </noise>
      </camera>
      <always_on>1</always_on>
      <update_rate>30</update_rate>
      <visualize>0</visualize>
    </sensor>
    <sensor name="cameraired1" type="camera">
      <camera name="camera">
        <horizontal_fov>1.4870205226991688</horizontal_fov>
        <image>
          <width>848</width>
          <height>480</height>
          <format>L_INT8</format>
        </image>
        <clip>
          <near>0.1</near>
          <far>100</far>
        </clip>
        <noise>
          <type>gaussian</type>
          <mean>0.0</mean>
          <stddev>0.05</stddev>
        </noise>
      </camera>
      <always_on>1</always_on>
      <update_rate>90</update_rate>
      <visualize>0</visualize>
    </sensor>
    <sensor name="cameraired2" type="camera">
      <camera name="camera">
        <horizontal_fov>1.4870205226991688</horizontal_fov>
        <image>
          <width>848</width>
          <height>480</height>
          <format>L_INT8</format>
        </image>
        <clip>
          <near>0.1</near>
          <far>100</far>
        </clip>
        <noise>
          <type>gaussian</type>
          <mean>0.0</mean>
          <stddev>0.05</stddev>
        </noise>
      </camera>
      <always_on>1</always_on>
      <update_rate>90</update_rate>
      <visualize>0</visualize>
    </sensor>
    <sensor name="cameradepth" type="depth">
      <camera name="camera">
        <horizontal_fov>1.4870205226991688</horizontal_fov>
        <image>
          <width>848</width>
          <height>480</height>
        </image>
        <clip>
          <near>0.1</near>
          <far>100</far>
        </clip>
        <noise>
          <type>gaussian</type>
          <mean>0.0</mean>
          <stddev>0.100</stddev>
        </noise>
      </camera>
      <always_on>1</always_on>
      <update_rate>90</update_rate>
      <visualize>0</visualize>
    </sensor>
  </gazebo>
  <gazebo>
    <plugin filename="librealsense_gazebo_plugin.so" name="camera">
      <prefix>camera</prefix>
      <depthUpdateRate>30.0</depthUpdateRate>
      <colorUpdateRate>30.0</colorUpdateRate>
      <infraredUpdateRate>30.0</infraredUpdateRate>
      <depthTopicName>depth/image_raw</depthTopicName>
      <depthCameraInfoTopicName>depth/camera_info</depthCameraInfoTopicName>
      <colorTopicName>color/image_raw</colorTopicName>
      <colorCameraInfoTopicName>color/camera_info</colorCameraInfoTopicName>
      <infrared1TopicName>infra1/image_raw</infrared1TopicName>
      <infrared1CameraInfoTopicName>infra1/camera_info</infrared1CameraInfoTopicName>
      <infrared2TopicName>infra2/image_raw</infrared2TopicName>
      <infrared2CameraInfoTopicName>infra2/camera_info</infrared2CameraInfoTopicName>
      <colorOpticalframeName>camera_color_optical_frame</colorOpticalframeName>
      <depthOpticalframeName>camera_depth_optical_frame</depthOpticalframeName>
      <infrared1OpticalframeName>camera_left_ir_optical_frame</infrared1OpticalframeName>
      <infrared2OpticalframeName>camera_right_ir_optical_frame</infrared2OpticalframeName>
      <rangeMinDepth>0.2</rangeMinDepth>
      <rangeMaxDepth>10.0</rangeMaxDepth>
      <pointCloud>True</pointCloud>
      <pointCloudTopicName>depth/color/points</pointCloudTopicName>
      <pointCloudCutoff>0.25</pointCloudCutoff>
      <pointCloudCutoffMax>9.0</pointCloudCutoffMax>
    </plugin>
  </gazebo>
  <link name="wheel_left_steering_link">
    <inertial>
      <origin rpy="0 0 0" xyz="0 0 0.1125"/>
      <inertia ixx="0.00484375" ixy="0" ixz="0" iyy="0.00484375" iyz="0" izz="0.0012500000000000002"/>
      <mass value="1"/>
    </inertial>
    <collision>
      <origin rpy="0 0 0" xyz="0 0 0"/>
      <geometry>
        <mesh filename="/home/hnk/auto_forklift_pallet_detection/src/forklift_simulator/urdf/RX20_16/meshes/steering_rod.dae"/>
      </geometry>
    </collision>
    <visual>
      <origin rpy="0 0 0" xyz="0 0 0"/>
      <geometry>
        <mesh filename="/home/hnk/auto_forklift_pallet_detection/src/forklift_simulator/urdf/RX20_16/meshes/steering_rod.dae"/>
      </geometry>
    </visual>
  </link>
  <joint name="wheel_left_steering_joint" type="revolute">
    <parent link="base_link"/>
    <child link="wheel_left_steering_link"/>
    <origin rpy="0 0 1.57" xyz="-1.429 0.404 0.06"/>
    <!-- <origin xyz="-0.662 0.247 0.115" rpy="0 0 0" /> -->
    <axis xyz="0 0 -1"/>
    <limit effort="30" lower="-1.0" upper="1.0" velocity="0.3"/>
    <dynamics damping="1" friction="1"/>
  </joint>
  <link name="wheel_left_link">
    <inertial>
      <origin rpy="0 0 0" xyz="0 0 0"/>
      <inertia ixx="0.00375" ixy="0" ixz="0" iyy="0.00375" iyz="0" izz="0.005625"/>
      <mass value="0.5"/>
    </inertial>
    <collision>
      <origin rpy="0 0 0" xyz="0 0 0"/>
      <geometry>
        <cylinder length="0.15" radius="0.15"/>
        <!-- <mesh filename="$(find forklift_simulator)/urdf/RX20_16/meshes/EVX_14_drive_wheel.dae" /> -->
      </geometry>
    </collision>
    <visual>
      <origin rpy="0 0 0" xyz="0 0 0"/>
      <geometry>
        <mesh filename="/home/hnk/auto_forklift_pallet_detection/src/forklift_simulator/urdf/RX20_16/meshes/rear_wheel.dae"/>
      </geometry>
    </visual>
  </link>
  <joint name="wheel_left_joint" type="continuous">
    <parent link="wheel_left_steering_link"/>
    <child link="wheel_left_link"/>
    <origin rpy="0 1.57 0" xyz=" 0 0 -0.09"/>
    <axis xyz="0 0 1"/>
    <!-- <joint_properties damping="1.0" friction="0.3"/> -->
    <limit effort="100" velocity="100"/>
    <dynamics damping="0.01" friction="0.0"/>
  </joint>
  <transmission name="trans_steering_left">
    <type>transmission_interface/SimpleTransmission</type>
    <joint name="wheel_left_steering_joint">
      <hardwareInterface>hardware_interface/PositionJointInterface</hardwareInterface>
    </joint>
    <actuator name="motor_steering_wheel_left">
      <hardwareInterface>hardware_interface/PositionJointInterface</hardwareInterface>
      <mechanicalReduction>1</mechanicalReduction>
    </actuator>
  </transmission>
  <transmission name="trans_dynamic_left">
    <type>transmission_interface/SimpleTransmission</type>
    <joint name="wheel_left_joint">
      <hardwareInterface>hardware_interface/VelocityJointInterface</hardwareInterface>
    </joint>
    <actuator name="motor_dynamic_wheel_left">
      <hardwareInterface>hardware_interface/VelocityJointInterface</hardwareInterface>
      <mechanicalReduction>1</mechanicalReduction>
    </actuator>
  </transmission>
  <gazebo reference="wheel_left_link">
    <mu1>1</mu1>
    <mu2>1</mu2>
    <!-- <kp>10000000.0</kp> -->
    <kp>1000000000.0</kp>
    <kd>1000.0</kd>
    <minDepth>0.002</minDepth>
    <maxVel>0</maxVel>
  </gazebo>
  <link name="wheel_right_steering_link">
    <inertial>
      <origin rpy="0 0 0" xyz="0 0 0.1125"/>
      <inertia ixx="0.00484375" ixy="0" ixz="0" iyy="0.00484375" iyz="0" izz="0.0012500000000000002"/>
      <mass value="1"/>
    </inertial>
    <collision>
      <origin rpy="0 0 0" xyz="0 0 0"/>
      <geometry>
        <mesh filename="/home/hnk/auto_forklift_pallet_detection/src/forklift_simulator/urdf/RX20_16/meshes/steering_rod.dae"/>
      </geometry>
    </collision>
    <visual>
      <origin rpy="0 0 0" xyz="0 0 0"/>
      <geometry>
        <mesh filename="/home/hnk/auto_forklift_pallet_detection/src/forklift_simulator/urdf/RX20_16/meshes/steering_rod.dae"/>
      </geometry>
    </visual>
  </link>
  <joint name="wheel_right_steering_joint" type="revolute">
    <parent link="base_link"/>
    <child link="wheel_right_steering_link"/>
    <origin rpy="0 0 1.57" xyz="-1.429 -0.404 0.06"/>
    <!-- <origin xyz="-0.662 0.247 0.115" rpy="0 0 0" /> -->
    <axis xyz="0 0 -1"/>
    <limit effort="30" lower="-1.0" upper="1.0" velocity="0.3"/>
    <dynamics damping="1" friction="1"/>
  </joint>
  <link name="wheel_right_link">
    <inertial>
      <origin rpy="0 0 0" xyz="0 0 0"/>
      <inertia ixx="0.00375" ixy="0" ixz="0" iyy="0.00375" iyz="0" izz="0.005625"/>
      <mass value="0.5"/>
    </inertial>
    <collision>
      <origin rpy="0 0 0" xyz="0 0 0"/>
      <geometry>
        <cylinder length="0.15" radius="0.15"/>
        <!-- <mesh filename="$(find forklift_simulator)/urdf/RX20_16/meshes/EVX_14_drive_wheel.dae" /> -->
      </geometry>
    </collision>
    <visual>
      <origin rpy="0 0 0" xyz="0 0 0"/>
      <geometry>
        <mesh filename="/home/hnk/auto_forklift_pallet_detection/src/forklift_simulator/urdf/RX20_16/meshes/rear_wheel.dae"/>
      </geometry>
    </visual>
  </link>
  <joint name="wheel_right_joint" type="continuous">
    <parent link="wheel_right_steering_link"/>
    <child link="wheel_right_link"/>
    <origin rpy="0 1.57 0" xyz=" 0 0 -0.09"/>
    <axis xyz="0 0 1"/>
    <!-- <joint_properties damping="1.0" friction="0.3"/> -->
    <limit effort="100" velocity="100"/>
    <dynamics damping="0.01" friction="0.0"/>
  </joint>
  <transmission name="trans_steering_right">
    <type>transmission_interface/SimpleTransmission</type>
    <joint name="wheel_right_steering_joint">
      <hardwareInterface>hardware_interface/PositionJointInterface</hardwareInterface>
    </joint>
    <actuator name="motor_steering_wheel_right">
      <hardwareInterface>hardware_interface/PositionJointInterface</hardwareInterface>
      <mechanicalReduction>1</mechanicalReduction>
    </actuator>
  </transmission>
  <transmission name="trans_dynamic_right">
    <type>transmission_interface/SimpleTransmission</type>
    <joint name="wheel_right_joint">
      <hardwareInterface>hardware_interface/VelocityJointInterface</hardwareInterface>
    </joint>
    <actuator name="motor_dynamic_wheel_right">
      <hardwareInterface>hardware_interface/VelocityJointInterface</hardwareInterface>
      <mechanicalReduction>1</mechanicalReduction>
    </actuator>
  </transmission>
  <gazebo reference="wheel_right_link">
    <mu1>1</mu1>
    <mu2>1</mu2>
    <!-- <kp>10000000.0</kp> -->
    <kp>1000000000.0</kp>
    <kd>1000.0</kd>
    <minDepth>0.002</minDepth>
    <maxVel>0</maxVel>
  </gazebo>
  <link name="wheel_right_driving_link">
    <inertial>
      <origin rpy="0 0 0" xyz="0 0 0"/>
      <inertia ixx="0.010799999999999999" ixy="0" ixz="0" iyy="0.010799999999999999" iyz="0" izz="0.0162"/>
      <mass value="1"/>
    </inertial>
    <collision>
      <origin rpy="0 0 0" xyz="0 0 0"/>
      <geometry>
        <cylinder length="0.18" radius="0.18"/>
      </geometry>
    </collision>
    <visual>
      <origin rpy="0 0 0" xyz="0 0 0"/>
      <geometry>
        <mesh filename="/home/hnk/auto_forklift_pallet_detection/src/forklift_simulator/urdf/RX20_16/meshes/front_wheel.dae"/>
      </geometry>
    </visual>
  </link>
  <joint name="wheel_right_driving_joint" type="continuous">
    <parent link="base_link"/>
    <child link="wheel_right_driving_link"/>
    <origin rpy="1.57 0 0" xyz="0.0 0.466 0.0"/>
    <axis xyz="0 0 -1"/>
    <!-- <joint_properties damping="1.0" friction="1.0"/> -->
    <limit effort="100" velocity="100"/>
    <dynamics damping="0.01" friction="1.0"/>
  </joint>
  <transmission name="trans_dynamic_right">
    <type>transmission_interface/SimpleTransmission</type>
    <joint name="wheel_right_driving_joint">
      <hardwareInterface>hardware_interface/VelocityJointInterface</hardwareInterface>
    </joint>
    <actuator name="motor_dynamic_wheel_right">
      <hardwareInterface>hardware_interface/VelocityJointInterface</hardwareInterface>
      <mechanicalReduction>1</mechanicalReduction>
    </actuator>
  </transmission>
  <gazebo reference="wheel_right_driving_link">
    <mu1>1.0</mu1>
    <mu2>1.0</mu2>
    <!-- <kp>10000000.0</kp> -->
    <kp>1000000000.0</kp>
    <kd>1000.0</kd>
    <minDepth>0.002</minDepth>
    <maxVel>0</maxVel>
  </gazebo>
  <link name="wheel_left_driving_link">
    <inertial>
      <origin rpy="0 0 0" xyz="0 0 0"/>
      <inertia ixx="0.010799999999999999" ixy="0" ixz="0" iyy="0.010799999999999999" iyz="0" izz="0.0162"/>
      <mass value="1"/>
    </inertial>
    <collision>
      <origin rpy="0 0 0" xyz="0 0 0"/>
      <geometry>
        <cylinder length="0.18" radius="0.18"/>
      </geometry>
    </collision>
    <visual>
      <origin rpy="0 0 0" xyz="0 0 0"/>
      <geometry>
        <mesh filename="/home/hnk/auto_forklift_pallet_detection/src/forklift_simulator/urdf/RX20_16/meshes/front_wheel.dae"/>
      </geometry>
    </visual>
  </link>
  <joint name="wheel_left_driving_joint" type="continuous">
    <parent link="base_link"/>
    <child link="wheel_left_driving_link"/>
    <origin rpy="1.57 0 0" xyz="0.0 -0.466 0.0"/>
    <axis xyz="0 0 -1"/>
    <!-- <joint_properties damping="1.0" friction="1.0"/> -->
    <limit effort="100" velocity="100"/>
    <dynamics damping="0.01" friction="1.0"/>
  </joint>
  <transmission name="trans_dynamic_left">
    <type>transmission_interface/SimpleTransmission</type>
    <joint name="wheel_left_driving_joint">
      <hardwareInterface>hardware_interface/VelocityJointInterface</hardwareInterface>
    </joint>
    <actuator name="motor_dynamic_wheel_left">
      <hardwareInterface>hardware_interface/VelocityJointInterface</hardwareInterface>
      <mechanicalReduction>1</mechanicalReduction>
    </actuator>
  </transmission>
  <gazebo reference="wheel_left_driving_link">
    <mu1>1.0</mu1>
    <mu2>1.0</mu2>
    <!-- <kp>10000000.0</kp> -->
    <kp>1000000000.0</kp>
    <kd>1000.0</kd>
    <minDepth>0.002</minDepth>
    <maxVel>0</maxVel>
  </gazebo>
  <!-- <xacro:nav_lidar name="one"  x="0.5"  y="0.0" z="1.8" roll="0" pitch="0" yaw="0.0" resolution="1"/> -->
  <!--xacro:detection_lidar name="front"  x="0.0"  y="0.0" z="2.0" roll="0" pitch="0" yaw="0" resolution="1"/-->
  <link name="back_nav_lidar">
    <inertial>
      <origin rpy="0 0 0" xyz="0 0 0"/>
      <inertia ixx="1.3333333333333332e-06" ixy="0" ixz="0" iyy="1.3333333333333332e-06" iyz="0" izz="2.0000000000000003e-06"/>
      <mass value="0.01"/>
    </inertial>
    <collision>
      <origin rpy="0 0 0" xyz="0 0 0"/>
      <geometry>
        <cylinder length="0.02" radius="0.02"/>
      </geometry>
    </collision>
    <visual>
      <origin rpy="0 0 0" xyz="0 0 0"/>
      <geometry>
        <cylinder length="0.02" radius="0.02"/>
      </geometry>
    </visual>
  </link>
  <gazebo reference="back_nav_lidar">
    <sensor name="/scan_back_nav_lidar_sensor" type="ray">
      <pose>0 0 0 0 0   0</pose>
      <visualize>false</visualize>
      <update_rate>20</update_rate>
      <ray>
        <scan>
          <horizontal>
            <samples>1440</samples>
            <resolution>1</resolution>
            <min_angle>0</min_angle>
            <max_angle>6.28</max_angle>
          </horizontal>
          <!-- <vertical>
              <samples>10</samples>
                <resolution>1</resolution>
              <min_angle>-0.5</min_angle>
                <max_angle>0.5</max_angle>
            </vertical> -->
        </scan>
        <range>
          <min>0.10</min>
          <max>10.0</max>
          <resolution>0.01</resolution>
        </range>
        <noise>
          <type>gaussian</type>
          <mean>0.0</mean>
          <stddev>0.001</stddev>
        </noise>
      </ray>
      <plugin filename="libgazebo_ros_laser.so" name="gazebo_ros_head_hokuyo_controller">
        <!-- <topicName>/${name}_nav_lidar</topicName> -->
        <topicName>/scan</topicName>
        <frameName>back_nav_lidar</frameName>
        <!-- <frameName>base_footprint</frameName> -->
      </plugin>
    </sensor>
  </gazebo>
  <joint name="lidar_joint_back" type="fixed">
    <parent link="base_scan"/>
    <child link="back_nav_lidar"/>
    <origin rpy="0 0 1.57" xyz="0.2 -0.6 -0.1"/>
    <axis xyz="0 0 1"/>
  </joint>
  <link name="front_nav_lidar">
    <inertial>
      <origin rpy="0 0 0" xyz="0 0 0"/>
      <inertia ixx="1.3333333333333332e-06" ixy="0" ixz="0" iyy="1.3333333333333332e-06" iyz="0" izz="2.0000000000000003e-06"/>
      <mass value="0.01"/>
    </inertial>
    <collision>
      <origin rpy="0 0 0" xyz="0 0 0"/>
      <geometry>
        <cylinder length="0.02" radius="0.02"/>
      </geometry>
    </collision>
    <visual>
      <origin rpy="0 0 0" xyz="0 0 0"/>
      <geometry>
        <cylinder length="0.02" radius="0.02"/>
      </geometry>
    </visual>
  </link>
  <gazebo reference="front_nav_lidar">
    <sensor name="/scan_front_nav_lidar_sensor" type="ray">
      <pose>0 0 0 0 0   0</pose>
      <visualize>false</visualize>
      <update_rate>20</update_rate>
      <ray>
        <scan>
          <horizontal>
            <samples>1440</samples>
            <resolution>1</resolution>
            <min_angle>0</min_angle>
            <max_angle>6.28</max_angle>
          </horizontal>
          <!-- <vertical>
              <samples>10</samples>
                <resolution>1</resolution>
              <min_angle>-0.5</min_angle>
                <max_angle>0.5</max_angle>
            </vertical> -->
        </scan>
        <range>
          <min>0.10</min>
          <max>10.0</max>
          <resolution>0.01</resolution>
        </range>
        <noise>
          <type>gaussian</type>
          <mean>0.0</mean>
          <stddev>0.001</stddev>
        </noise>
      </ray>
      <plugin filename="libgazebo_ros_laser.so" name="gazebo_ros_head_hokuyo_controller">
        <!-- <topicName>/${name}_nav_lidar</topicName> -->
        <topicName>/scan</topicName>
        <frameName>front_nav_lidar</frameName>
        <!-- <frameName>base_footprint</frameName> -->
      </plugin>
    </sensor>
  </gazebo>
  <joint name="lidar_joint_front" type="fixed">
    <parent link="base_scan"/>
    <child link="front_nav_lidar"/>
    <origin rpy="0 0 -1.57" xyz="0 0.4 0.1"/>
    <axis xyz="0 0 1"/>
  </joint>
  <link name="rear_steer_link">
    <visual>
      <origin rpy="0 0 0" xyz="0 0 0"/>
      <geometry>
        <cylinder length="0.02" radius="0.05"/>
      </geometry>
      <material name="yellow"/>
    </visual>
    <collision>
      <origin rpy="0 0 0" xyz="0 0 0"/>
      <geometry>
        <cylinder length="0.02" radius="0.05"/>
      </geometry>
    </collision>
    <inertial>
      <origin rpy="0 0 0" xyz="0 0 0"/>
      <mass value="1"/>
      <inertia ixx="0.0006583333333333334" ixy="0.0" ixz="0.0" iyy="0.0006583333333333334" iyz="0.0" izz="0.0012500000000000002"/>
    </inertial>
  </link>
  <joint name="rear_steer_joint" type="revolute">
    <parent link="base_link"/>
    <child link="rear_steer_link"/>
    <origin rpy="0 0 0" xyz="0.15750000000000003 0 0.1754"/>
    <axis xyz="0 0 1"/>
    <limit effort="10.0" lower="-3.141592653589793" upper="3.141592653589793" velocity="5.0"/>
  </joint>
  <transmission name="rear_steer_joint_trans">
    <type>transmission_interface/SimpleTransmission</type>
    <actuator name="rear_steer_joint_motor">
      <mechanicalReduction>1</mechanicalReduction>
      <hardwareInterface>hardware_interface/PositionJointInterface</hardwareInterface>
    </actuator>
    <joint name="rear_steer_joint">
      <hardwareInterface>hardware_interface/PositionJointInterface</hardwareInterface>
    </joint>
  </transmission>
  <gazebo reference="rear_steer_link">
    <material>Gazebo/Yellow</material>
  </gazebo>
  <link name="rear_wheel_link">
    <visual>
      <origin rpy="0 0 0" xyz="0 0 0"/>
      <geometry>
        <cylinder length="0.075" radius="0.0375"/>
      </geometry>
      <material name="yellow"/>
    </visual>
    <collision>
      <origin rpy="0 0 0" xyz="0 0 0"/>
      <geometry>
        <cylinder length="0.075" radius="0.0375"/>
      </geometry>
    </collision>
    <inertial>
      <origin rpy="0 0 0" xyz="0 0 0"/>
      <mass value="0.03125"/>
      <inertia ixx="2.5634765624999996e-05" ixy="0.0" ixz="0.0" iyy="2.5634765624999996e-05" iyz="0.0" izz="2.197265625e-05"/>
    </inertial>
  </link>
  <joint name="rear_wheel_joint" type="continuous">
    <parent link="base_link"/>
    <child link="rear_wheel_link"/>
    <origin rpy="-1.5707963267948966 0 0" xyz="-0.15750000000000003 0 0"/>
    <axis xyz="0 0 1"/>
  </joint>
  <transmission name="rear_wheel_joint_trans">
    <type>transmission_interface/SimpleTransmission</type>
    <actuator name="rear_wheel_joint_motor">
      <mechanicalReduction>1</mechanicalReduction>
      <hardwareInterface>hardware_interface/VelocityJointInterface</hardwareInterface>
    </actuator>
    <joint name="rear_wheel_joint">
      <hardwareInterface>hardware_interface/VelocityJointInterface</hardwareInterface>
    </joint>
  </transmission>
  <gazebo reference="rear_wheel_link">
    <material>Gazebo/Yellow</material>
  </gazebo>
</robot>

