<?xml version="1.0" ?>
<robot name="wheel" xmlns:xacro="http://www.ros.org/wiki/xacro">

<xacro:include filename="$(find forklift_simulator)/urdf/RX20_16/materials.xacro"/>
<xacro:include filename="$(find forklift_simulator)/urdf/RX20_16/inertials.xacro"/>

<xacro:property name="steer_effort" value="100.0"/>
<xacro:property name="steer_velocity" value="5.0"/>
<xacro:property name="steer_limit_deg" value="45.0"/>
<xacro:macro name="rear_steer"
        params="
        name
        parent
        steer_radius
        steer_thickness
        steer_mass
        base_length
        base_width
        axle_offset
        steer_height">
        <link name="${name}_steer_link">
      <visual>
        <origin xyz="0 0 0" rpy="0 0 0"/>
        <geometry>
          <cylinder radius="${steer_radius}" length="${steer_thickness}"/>
        </geometry>
        <material name="yellow" />
      </visual>
      <collision>
        <origin xyz="0 0 0" rpy="0 0 0"/>
        <geometry>
          <cylinder radius="${steer_radius}" length="${steer_thickness}"/>
        </geometry>
      </collision>
      <xacro:solid_cylinder_inertial 
          rpy="0 0 0" xyz="0 0 0"
          mass="${steer_mass}"
          radius="${steer_radius}" length="${steer_thickness}" />
    </link>

    <joint name="${name}_steer_joint" type="revolute">
      <parent link="${parent}_link"/>
      <child link="${name}_steer_link"/>
      <origin xyz="-1.429 0 ${steer_height}" rpy="0 0 0"/>
      <axis xyz="0 0 1"/>
      <limit effort="${steer_effort}"
             lower="${-180.0 * deg_to_rad}" upper="${180.0 * deg_to_rad}"
             velocity="${steer_velocity}"/>
    </joint>

    <transmission name="${name}_steer_joint_trans">
      <type>transmission_interface/SimpleTransmission</type>
      <actuator name="${name}_steer_joint_motor">
        <mechanicalReduction>1</mechanicalReduction>
        <hardwareInterface>hardware_interface/PositionJointInterface</hardwareInterface>
      </actuator>
      <joint name="${name}_steer_joint">
        <hardwareInterface>hardware_interface/PositionJointInterface</hardwareInterface>
      </joint>
    </transmission>

    <gazebo reference="${name}_steer_link">
      <material>Gazebo/Yellow</material>
    </gazebo>

    </xacro:macro>
   

    <xacro:macro name="rear_wheel"
    params="
      name
      parent
      wheel_radius
      wheel_thickness
      wheel_mass
      *origin">
    <link name="${name}_wheel_link">
      <visual>
        <origin xyz="0 0 0" rpy="0 0 0"/>
        <geometry>
          <cylinder radius="${wheel_radius}" length="${wheel_thickness}"/>
        </geometry>
        <material name="yellow" />
      </visual>
      <collision>
        <origin xyz="0 0 0" rpy="0 0 0"/>
        <geometry>
          <cylinder radius="${wheel_radius}" length="${wheel_thickness}"/>
        </geometry>
      </collision>
      <xacro:solid_cylinder_inertial 
          rpy="0 0 0" xyz="0 0 0"
          mass="${wheel_mass}"
          radius="${wheel_radius}" length="${wheel_thickness}" />
    </link>

    <joint name="${name}_wheel_joint" type="continuous">
      <parent link="${parent}_link"/>
      <child link="${name}_wheel_link"/>
      <xacro:insert_block name="origin"/>
      <axis xyz="0 0 1"/>
    </joint>

    <transmission name="${name}_wheel_joint_trans">
      <type>transmission_interface/SimpleTransmission</type>
      <actuator name="${name}_wheel_joint_motor">
        <mechanicalReduction>1</mechanicalReduction>
        <hardwareInterface>hardware_interface/VelocityJointInterface</hardwareInterface>
      </actuator>
      <joint name="${name}_wheel_joint">
        <hardwareInterface>hardware_interface/VelocityJointInterface</hardwareInterface>
      </joint>
    </transmission>

    <gazebo reference="${name}_wheel_link">
      <material>Gazebo/Yellow</material>
    </gazebo>
  </xacro:macro>


   <xacro:macro name="rear_wheel_lr"
    params="
      name
      parent
      reflect
      x_steering 
      y_steering 
      z_steering
      wheel_radius
      wheel_thickness
      wheel_mass
      steer_radius
      steer_thickness
      steer_mass
      base_length
      base_width
      flip
      axle_offset
      steer_height">
    <link name="${name}_steer_link">
      <visual>
        <origin xyz="0 0 0" rpy="0 0 0"/>
        <geometry>
          <cylinder radius="${steer_radius}" length="${steer_thickness}"/>
        </geometry>
        <material name="blue" />
      </visual>
      <collision>
        <origin xyz="0 0 0" rpy="0 0 0"/>
        <geometry>
          <cylinder radius="${steer_radius}" length="${steer_thickness}"/>
        </geometry>
      </collision>
      <xacro:solid_cylinder_inertial 
          rpy="0 0 0" xyz="0 0 0"
          mass="${steer_mass}"
          radius="${steer_radius}" length="${steer_thickness}" />
    </link>

    <joint name="${name}_steer_joint" type="revolute">
      <parent link="${parent}_link"/>
      <child link="${name}_steer_link"/>
      <origin xyz="${x_steering} ${y_steering} ${z_steering }" rpy="0 0 0" />
      <axis xyz="0 0 ${1*flip}"/>
      <limit effort="${steer_effort}"
             lower="${steer_limit_deg * deg_to_rad * -1.0}" upper="${steer_limit_deg * deg_to_rad}"
             velocity="${steer_velocity}"/>
    </joint>

    <link name="${name}_wheel_link">
      <visual>
        <origin xyz="0 0 0" rpy="0 0 0"/>
        <geometry>
          <cylinder radius="${wheel_radius}" length="${wheel_thickness}"/>
        </geometry>
        <material name="red" />
      </visual>
      <collision>
        <origin xyz="0 0 0" rpy="0 0 0"/>
        <geometry>
          <cylinder radius="${wheel_radius}" length="${wheel_thickness}"/>
        </geometry>
      </collision>
      <xacro:solid_cylinder_inertial 
          rpy="0 0 0" xyz="0 0 0"
          mass="${wheel_mass}"
          radius="${wheel_radius}" length="${wheel_thickness}" />
    </link>

    <joint name="${name}_wheel_joint" type="continuous">
      <parent link="${name}_steer_link"/>
      <child link="${name}_wheel_link"/>
      <origin xyz="0 0 ${-steer_height}" rpy="${-90 * deg_to_rad} 0 0"/>
      <axis xyz="0 0 1"/>
    </joint>

    <transmission name="${name}_steer_joint_trans">
      <type>transmission_interface/SimpleTransmission</type>
      <actuator name="${name}_steer_joint_motor">
        <mechanicalReduction>1</mechanicalReduction>
        <hardwareInterface>hardware_interface/EffortJointInterface</hardwareInterface>
      </actuator>
      <joint name="${name}_steer_joint">
        <hardwareInterface>hardware_interface/EffortJointInterface</hardwareInterface>
      </joint>
    </transmission>

    <transmission name="${name}_wheel_joint_trans">
      <type>transmission_interface/SimpleTransmission</type>
      <actuator name="${name}_wheel_joint_motor">
        <mechanicalReduction>1</mechanicalReduction>
        <hardwareInterface>hardware_interface/EffortJointInterface</hardwareInterface>
      </actuator>
      <joint name="${name}_wheel_joint">
        <hardwareInterface>hardware_interface/EffortJointInterface</hardwareInterface>
      </joint>
    </transmission>

    <gazebo reference="${name}_steer_link">
      <material>Gazebo/Blue</material>
    </gazebo>
    
    <gazebo reference="${name}_wheel_link">
      <material>Gazebo/Red</material>
    </gazebo>
  </xacro:macro>


   <xacro:macro name="front_wheel_lr" params="name parent x_loading y_loading z_loading radius width flip">

    <link name="wheel_${name}_driving_link">
      <inertial>
      <origin xyz="0 0 0" rpy="0 0 0"/>
      <xacro:cylinder_inertia mass="1" r="${radius}" l="${width}" />
      <mass value= "1"/>
      </inertial>

      <collision >
        <origin xyz="0 0 0" rpy="0 0 0"/>
        <geometry>
            <cylinder radius="${radius}" length="${width}"/>
        </geometry>
      </collision>

      <visual>
      <origin xyz="0 0 0" rpy="0 0 0"/>
      <geometry>
          <mesh filename="$(find forklift_simulator)/urdf/RX20_16/meshes/front_wheel.dae" />
      </geometry>
      </visual>
    </link>
      
    <joint name="wheel_${name}_driving_joint" type="continuous">
      <parent link="${parent}_link" />
      <child link="wheel_${name}_driving_link" />
      <origin xyz="${x_loading} ${y_loading} ${z_loading}" rpy="1.57 0 0" />
      <axis xyz="0 0 ${1*flip}" />
      <!-- <joint_properties damping="1.0" friction="1.0"/> -->
      <limit effort="100" velocity="100"/>
      <dynamics damping="0.1" friction="2.0"/>
    </joint>

    <transmission name="trans_dynamic_${name}">
      <type>transmission_interface/SimpleTransmission</type>
      <joint name="wheel_${name}_driving_joint">
        <hardwareInterface>hardware_interface/EffortJointInterface</hardwareInterface>
      </joint>
      <actuator name="motor_dynamic_wheel_${name}">
        <hardwareInterface>hardware_interface/EffortJointInterface</hardwareInterface>
        <mechanicalReduction>1</mechanicalReduction>
      </actuator>
    </transmission>

    <gazebo reference="wheel_${name}_driving_link">
        <mu1>1.0</mu1>
        <mu2>1.0</mu2>
        <!-- <kp>10000000.0</kp> -->
        <kp>1000000000.0</kp>
        <kd>1000.0</kd>
        <minDepth>0.002</minDepth>
        <maxVel>0</maxVel>		
      </gazebo>

  </xacro:macro>
 
</robot>
